Traceback (most recent call last):
  File "C:\hostedtoolcache\windows\Python\3.9.13\x64\lib\site-packages\jupyter_cache\executors\utils.py", line 58, in single_nb_execution
    executenb(
  File "C:\hostedtoolcache\windows\Python\3.9.13\x64\lib\site-packages\nbclient\client.py", line 1204, in execute
    return NotebookClient(nb=nb, resources=resources, km=km, **kwargs).execute()
  File "C:\hostedtoolcache\windows\Python\3.9.13\x64\lib\site-packages\nbclient\util.py", line 84, in wrapped
    return just_run(coro(*args, **kwargs))
  File "C:\hostedtoolcache\windows\Python\3.9.13\x64\lib\site-packages\nbclient\util.py", line 62, in just_run
    return loop.run_until_complete(coro)
  File "C:\hostedtoolcache\windows\Python\3.9.13\x64\lib\asyncio\base_events.py", line 647, in run_until_complete
    return future.result()
  File "C:\hostedtoolcache\windows\Python\3.9.13\x64\lib\site-packages\nbclient\client.py", line 663, in async_execute
    await self.async_execute_cell(
  File "C:\hostedtoolcache\windows\Python\3.9.13\x64\lib\site-packages\nbclient\client.py", line 965, in async_execute_cell
    await self._check_raise_for_error(cell, cell_index, exec_reply)
  File "C:\hostedtoolcache\windows\Python\3.9.13\x64\lib\site-packages\nbclient\client.py", line 862, in _check_raise_for_error
    raise CellExecutionError.from_cell_and_msg(cell, exec_reply_content)
nbclient.exceptions.CellExecutionError: An error occurred while executing the following cell:
------------------
print(X_train_tfidf.toarray()[0:3, :])
------------------

[1;31m---------------------------------------------------------------------------[0m
[1;31mMemoryError[0m                               Traceback (most recent call last)
Cell [1;32mIn[10], line 1[0m
[1;32m----> 1[0m [38;5;28mprint[39m([43mX_train_tfidf[49m[38;5;241;43m.[39;49m[43mtoarray[49m[43m([49m[43m)[49m[[38;5;241m0[39m:[38;5;241m3[39m, :])

File [1;32mC:\hostedtoolcache\windows\Python\3.9.13\x64\lib\site-packages\scipy\sparse\_compressed.py:1051[0m, in [0;36m_cs_matrix.toarray[1;34m(self, order, out)[0m
[0;32m   1049[0m [38;5;28;01mif[39;00m out [38;5;129;01mis[39;00m [38;5;28;01mNone[39;00m [38;5;129;01mand[39;00m order [38;5;129;01mis[39;00m [38;5;28;01mNone[39;00m:
[0;32m   1050[0m     order [38;5;241m=[39m [38;5;28mself[39m[38;5;241m.[39m_swap([38;5;124m'[39m[38;5;124mcf[39m[38;5;124m'[39m)[[38;5;241m0[39m]
[1;32m-> 1051[0m out [38;5;241m=[39m [38;5;28;43mself[39;49m[38;5;241;43m.[39;49m[43m_process_toarray_args[49m[43m([49m[43morder[49m[43m,[49m[43m [49m[43mout[49m[43m)[49m
[0;32m   1052[0m [38;5;28;01mif[39;00m [38;5;129;01mnot[39;00m (out[38;5;241m.[39mflags[38;5;241m.[39mc_contiguous [38;5;129;01mor[39;00m out[38;5;241m.[39mflags[38;5;241m.[39mf_contiguous):
[0;32m   1053[0m     [38;5;28;01mraise[39;00m [38;5;167;01mValueError[39;00m([38;5;124m'[39m[38;5;124mOutput array must be C or F contiguous[39m[38;5;124m'[39m)

File [1;32mC:\hostedtoolcache\windows\Python\3.9.13\x64\lib\site-packages\scipy\sparse\_base.py:1298[0m, in [0;36mspmatrix._process_toarray_args[1;34m(self, order, out)[0m
[0;32m   1296[0m     [38;5;28;01mreturn[39;00m out
[0;32m   1297[0m [38;5;28;01melse[39;00m:
[1;32m-> 1298[0m     [38;5;28;01mreturn[39;00m [43mnp[49m[38;5;241;43m.[39;49m[43mzeros[49m[43m([49m[38;5;28;43mself[39;49m[38;5;241;43m.[39;49m[43mshape[49m[43m,[49m[43m [49m[43mdtype[49m[38;5;241;43m=[39;49m[38;5;28;43mself[39;49m[38;5;241;43m.[39;49m[43mdtype[49m[43m,[49m[43m [49m[43morder[49m[38;5;241;43m=[39;49m[43morder[49m[43m)[49m

[1;31mMemoryError[0m: Unable to allocate 25.3 GiB for an array with shape (46064, 73634) and data type float64
MemoryError: Unable to allocate 25.3 GiB for an array with shape (46064, 73634) and data type float64

